<?xml version="1.0" encoding="utf-8"?>
<robot name="URDF_Robot" xmlns:xacro="http://www.ros.org/wiki/xacro">
  <!-- Include your STL paths as parameters -->
  <xacro:property name="base_link_mesh" value="package://robot_diff/meshes/base_link.STL"/>
  <xacro:property name="right_wheel_mesh" value="package://robot_diff/meshes/right_wheel.STL"/>
  <xacro:property name="left_wheel_mesh" value="package://robot_diff/meshes/left_wheel.STL"/>
  <xacro:property name="carcasa_mesh" value="package://robot_diff/meshes/Carcasa.STL"/>
  <xacro:property name="lidar_mesh" value="package://robot_diff/meshes/Lidar_link.STL"/>
  <xacro:property name="kinect_mesh" value="package://robot_diff/meshes/Kinect_link.STL"/>

  <link name="base_link">
    <inertial>
      <origin xyz="0.0045272 2.4147E-15 0.34647" rpy="0 0 0" />
      <mass value="8.4929" />
      <inertia ixx="0.055815" ixy="-6.4277E-05" ixz="2.5223E-06" iyy="0.062727" iyz="0.0014237" izz="0.073696" />
    </inertial>
    <visual>
      <origin xyz="0 0 0" rpy="0 0 0" />
      <geometry>
        <mesh filename="${base_link_mesh}" />
      </geometry>
      <material name="">
        <color rgba="0.65098 0.61961 0.58824 1" />
      </material>
    </visual>
    <collision>
      <origin xyz="0 0 0" rpy="0 0 0" />
      <geometry>
        <mesh filename="${base_link_mesh}" />
      </geometry>
    </collision>
  </link>

  <link name="right_wheel">
    <inertial>
      <origin xyz="-1.1102E-16 -0.03 0" rpy="0 0 0" />
      <mass value="1.9224" />
      <inertia ixx="0.0063801" ixy="-4.796E-19" ixz="-1.062E-19" iyy="0.011839" iyz="6.3001E-19" izz="0.0063801" />
    </inertial>
    <visual>
      <origin xyz="0 0 0" rpy="0 0 0" />
      <geometry>
        <mesh filename="${right_wheel_mesh}" />
      </geometry>
      <material name="">
        <color rgba="0.79216 0.81961 0.93333 1" />
      </material>
    </visual>
    <collision>
      <origin xyz="0 0 0" rpy="0 0 0" />
      <geometry>
        <mesh filename="${right_wheel_mesh}" />
      </geometry>
    </collision>
  </link>

  <joint name="joint_right_wheel" type="continuous">
    <origin xyz="0.00425 -0.24475 0.10979" rpy="0 0 0" />
    <parent link="base_link" />
    <child link="right_wheel" />
    <axis xyz="0 1 0" />
  </joint>

  <link name="left_wheel">
    <inertial>
      <origin xyz="0 0.03 0" rpy="0 0 0" />
      <mass value="1.9224" />
      <inertia ixx="0.0063801" ixy="-1.3791E-19" ixz="-3.8919E-19" iyy="0.011839" iyz="-5.6319E-19" izz="0.0063801" />
    </inertial>
    <visual>
      <origin xyz="0 0 0" rpy="0 0 0" />
      <geometry>
        <mesh filename="${left_wheel_mesh}" />
      </geometry>
      <material name="">
        <color rgba="0.79216 0.81961 0.93333 1" />
      </material>
    </visual>
    <collision>
      <origin xyz="0 0 0" rpy="0 0 0" />
      <geometry>
        <mesh filename="${left_wheel_mesh}" />
      </geometry>
    </collision>
  </link>

  <joint name="joint_left_wheel" type="continuous">
    <origin xyz="0.00675 0.24475 0.10979" rpy="0 0 0" />
    <parent link="base_link" />
    <child link="left_wheel" />
    <axis xyz="0 1 0" />
  </joint>

  <link name="Carcasa">
    <inertial>
      <origin xyz="0.035854 0.045075 0.34163" rpy="0 0 0" />
      <mass value="12.342" />
      <inertia ixx="0.3505" ixy="2.0646E-06" ixz="-0.0035872" iyy="0.29139" iyz="-3.7841E-06" izz="0.39506" />
    </inertial>
    <visual>
      <origin xyz="0 0 0" rpy="0 0 0" />
      <geometry>
        <mesh filename="${carcasa_mesh}" />
      </geometry>
      <material name="">
        <color rgba="0.79216 0.81961 0.93333 1" />
      </material>
    </visual>
    <collision>
      <origin xyz="0 0 0" rpy="0 0 0" />
      <geometry>
        <mesh filename="${carcasa_mesh}" />
      </geometry>
    </collision>
  </link>

  <joint name="joint_carcasa" type="fixed">
    <origin xyz="0 0 0.013293" rpy="0 0 0" />
    <parent link="base_link" />
    <child link="Carcasa" />
    <axis xyz="0 0 0" />
  </joint>

  <link name="Lidar_link">
    <inertial>
      <origin xyz="9.1926E-05 -0.0074835 0.010668" rpy="0 0 0" />
      <mass value="1.3308" />
      <inertia ixx="0.0009607" ixy="8.0198E-07" ixz="3.0916E-06" iyy="0.00061492" iyz="0.00015824" izz="0.0010982" />
    </inertial>
    <visual>
      <origin xyz="0 0 0" rpy="0 0 0" />
      <geometry>
        <mesh filename="${lidar_mesh}" />
      </geometry>
      <material name="">
        <color rgba="0.79216 0.81961 0.93333 1" />
      </material>
    </visual>
    <collision>
      <origin xyz="0 0 0" rpy="0 0 0" />
      <geometry>
        <mesh filename="${lidar_mesh}" />
      </geometry>
    </collision>
  </link>

  <joint name="joint_lidar" type="fixed">
    <origin xyz="0.2225 0.014498 0.30689" rpy="0 0 -1.5708" />
    <parent link="base_link" />
    <child link="Lidar_link" />
    <axis xyz="0 0 0" />
  </joint>

  <link name="Kinect_link">
    <inertial>
      <origin xyz="0 0 0" rpy="0 0 0" />
      <mass value="0" />
      <inertia ixx="0" ixy="0" ixz="0" iyy="0" iyz="0" izz="0" />
    </inertial>
    <visual>
      <origin xyz="0 0 0" rpy="0 0 0" />
      <geometry>
        <mesh filename="${kinect_mesh}" />
      </geometry>
      <material name="">
        <color rgba="1 1 1 1" />
      </material>
    </visual>
    <collision>
      <origin xyz="0 0 0" rpy="0 0 0" />
      <geometry>
        <mesh filename="${kinect_mesh}" />
      </geometry>
    </collision>
  </link>

  <joint name="joint_kinect" type="fixed">
    <origin xyz="0.174465135528564 0.00688258604257161 0.38554299031729" rpy="-1.5708 0 -1.5708" />
    <parent link="base_link" />
    <child link="Kinect_link" />
    <axis xyz="0 0 0" />
  </joint>
</robot>

